Workbook

Sheet Table 1
B2: FORM NO. 15CA [See rule 37BB] Information to be furnished for payments, to a non- resident not being a company, or to a foreign company
B3: PART A - To be filled up if the remittance is chargeable to tax under the provisions of the Income-tax Act,1961 and the remittance or the aggregate of such remittances, as the case may be, does not exceed five lakh rupees during the financial year.
B4: PART B - To be filled up if the remittance is chargeable to tax under the provisions of the Income-tax Act,1961 and the remittance or the aggregate of such remittances, as the case may be, exceeds five lakh rupees during the financial year and an order/ certificate u/s 195(2)/ 195(3)/ 197 of Income-tax Act has been obtained from the Assessing Officer.
B5: PART C - To be filled up if the remittance is chargeable to tax under the provisions of Income-tax Act, 1961 and the remittance or the aggregate of such remittances, as the case may be, exceeds five lakh rupees during the financial year and a certificate in Form No. 15CB from an accountant as defined in the Explanation below sub-section (2) of section 288 has been obtained.
B6: PART D - To be filled up if the remittance is not chargeable to tax under the provisions of the Income-tax Act,1961 {other than payments referred to in rule 37BB(3)} by the person referred to in rule 37BB(2).
B7: Please select the relevant part from the drop down. PART - D
B8: PART - D To be filled up if the remittance is not chargeable to tax under the provisions of the Income-tax Act,1961 {other than payments referred to in rule 37BB(3)} by the person referred to in rule 37BB(2).
B9: REMITTER
B10: Name of Remitter
B11: PAN of the Remitter (if available)
B12: TAN of the Remitter (if available)
B13: ADDRESS OF THE REMITTER
... B40: Country to which remittance is made
B41: Country | C41: =C36 -> 0
B42: Name of Country if selected as Others
B43: Currency | C43: ='Basic Data'!C7 -> USD
B44: Currency if selected as Others
B45: Country of which the recipient of remittance is resident, if available | C45: =C41 -> 0
B46: REMITTANCE
B47: Amount payable
B48: In foreign currency: | G48: 2150
B49: In Indian Rs. | G49: 159573
B50: Name of bank
B51: Name of Bank if selected as Other Bank
B52: Name of the branch of the bank
B53: BSR code of the bank branch (7 digit)
B54: Proposed date of remittance (DD/MM/YYYY)
B55: Nature of remittance as per agreement/ document
B56: Nature of remittance as per agreement/ document if Others
B57: Relevant purpose code as per RBI
B59: 2. I certify that I have reason to believe that the remittance as above is not chargeable under the provision of Income-tax Act 1961 and is not liable for deduction of tax at source.
B60: PART-D VERIFICATION
B61: 1. I, RAJNIKANT VYAS(full name in block letters) son/daughter of GANDALAL VYAS in the capacity of DIRECT OR (designation) solemnly declare that the information given above is true to the best of my knowledge and belief and no relevant information has been concealed
B62: 2. In case where it is found that the tax actually deductible on the amount of remittance has not been deducted or after deduction has not been paid or not paid in full I undertake to pay the amount of tax not deducted or not paid, as the case may be along with interest due. I shall also be subject to the provisions of penalty for the said default as per the provisions of the Income-tax Act, 1961
... B68: This form has been digitally signed by RAJNIKANT GANDALAL VYAS having PAN AACPV0781F from IP Address 118.185.201.75 on 2020-05-26 16:28:06.0 . Dsc Sl No and issuer 2473381488649837714CN=SafeScrypt sub-CA for RCAI Class 2 2014,OU=Sub-CA,O=Sify Technologies Limited,C=IN

Sheet Revised Form15CB
A1: Tax Documents | E1: Sr. No. | F1: ='Basic Data'!N1 -> 0040 - MLSPL
A2: TRC | C2: 2024 | E2: Document No. | F2: 19/35555/56/57
A3: PE | C3: 2024 | E3: Purpose Code | F3: S 1006
A4: 10F | C4: 2024
B11: FORM NO. 15CB
B12: (See rule 37BB)
B13: Certificate of an accountant*
B14: We have examined the agreement (wherever applicable) between
B15: M/s Meril Life Sciences Pvt. Ltd. (Remitter)
B16: and
B17: ='Basic Data'!E4 -> 0
B18: requiring the above remittance as well as the relevant documents and books of account required for ascertaining the nature of remittance and for determining the rate of deduction of tax at source as per provisions of Charter- XVII-B. We hereby certify the following:-
B19: A | C19: Name and address of the beneficiary of the remittance:
D20: ='Basic Data'!C4 -> K & C Medical Co. Ltd.
D21: ='Basic Data'!C5 -> 4F, No 53, Lane 147, Anxiang Road, Xindia District, New Taipei City, R.O.C. 10041
B22: B | C22: 1 | D22: Country to which remittance is made | E22: Country: | F22: Currency:
E23: ='Basic Data'!C6 -> Taiwan | F23: ='Basic Data'!C7 -> USD
C24: 2 | D24: Amount payable | E24: In foreign currency | F24: In Indian Rs.
E25: ='Basic Data'!G10 -> USD 26833.33 | F25: ='Basic Data'!E10 -> 2308423
F26: ='Basic Data'!E16 -> (approx) @ 86.028212
C27: 3 | D27: Name of the bank and Branch | E27: ='Basic Data'!G23 -> Kotak Mahindra Bank Plot No. 586, Mahalaxmi Society, Vapi Daman Road, Chala, Vapi
C28: 4 | D28: BSR Code of the bank branch (7 digit) | E28: ='Basic Data'!G24 -> 5560065
C29: 5 | D29: Proposed date of remittance | E29: ='Basic Data'!C26 -> 45766
C30: 6 | D30: Nature of remittance as per agreement/ document. | E30: Consultancy fees
C31: 7 | D31: In case the remittance is net of taxes, whether tax payable has been grossed up? | E31: Yes
C32: 8 | D32: Taxability under the provision of Income Tax Act (without considering DTAA)
D33: (a) the relevant section of the act under which the remittance is covered | E33: According to the information and explanation given to us and on the basis of documents produced before us, since the payment is made as Consultancy fees, the said services falls under Section 9(1)(vii) of Income Tax Act, 1961.
D34: (b) the amount of income chargeable to tax | E34: ='Basic Data'!O10&'Basic Data'!P10 -> Rs. 2623209
D35: (c) the tax liability | E35: ="Rs. "&'Basic Data'!P11 -> Rs. 545627 | G35: =21646/104066% -> 20.800261
D36: (d) basis of determining taxable income and tax liability | E36: Consultancy fees falls under the definition of fees for technical services provided under explanation 2 to section 9(1)(vii). Tax @ 20.80% specified under section 115A(1)(b) of Income Tax Act, 1961.
C39: 9 | D39: If any relief is claimed under DTAA-
D40: (i) whether tax residency certificate is obtained from the recipient of remittance | E40: Yes
D41: (ii) please specify relevant DTAA | E41: India Taipei DTAA
D42: (ii) please specify relevant article of DTAA | E42: =E46 -> Article 12 - Royalties and Fees for Technical Services of India-Taipei DTAA
D43: (iii) taxable income as per DTAA | E43: In Indian | F43: =+'Basic Data'!E10 -> 2308423
D44: (iv) tax liability as per DTAA | E44: In Indian | F44: =+'Basic Data'!E11 -> 230842
D45: A.If the remittance is for royalties, fee for technical services, interest, dividend etc. (not connected with permanent establishment) please indicate :- | E45: Yes
D46: (a) Article of DTAA | E46: Article 12 - Royalties and Fees for Technical Services of India-Taipei DTAA | H46: Article 13 - Royalties And Fees For Technical Services And Payments For The Use Of Equipment
D47: (b) Rate of TDS required to be deducted in terms of such article of the applicable DTAA | E47: As per DTAA (%) | F47: 0.1
D48: B. In case the remittance is on account of business income, please indicate:- | E48: No
...

Sheet Basic Data
N1: 0040 - MLSPL
J2: VAT | L2: Invoice Amount | N2: Document No. | O2: Invoice NO.
B3: Vendor Code | K3: 1 | L3: 750 | N3: 19/35555 | O3: ML103/Mar/2025
B4: Vendor Name | C4: K & C Medical Co. Ltd. | D4: (Beneficiary) | K4: 2 | L4: 12400 | N4: 19/35556 | O4: ML102/Mar/2025
B5: Address: | C5: 4F, No 53, Lane 147, Anxiang Road, Xindia District, New Taipei City, R.O.C. 10041 | D5: Email | I5: =111.11+144.44+83.33 -> 338.88 | K5: 3 | L5: 11000 | N5: 19/35557 | O5: ML100/Mar/2025 | AF5: SPECIFIED LIST
B6: Country: | C6: Taiwan | D6: Contact No. | I6: =9191.02+11948.08+6893.06 -> 28032.16 | K6: 4
B7: Currency: | C7: USD | D7: Tax ID | L7: =SUM(L3:L6) -> 24150 | AF7: Sl. No. | AG7: Purpose code as per RBI | AH7: Nature of payment
C8: 90 | AF8: -1 | AG8: -2 | AH8: -3
C9: Amount | D9: Ex. Rate | E9: INR Amount | F9: Curreny | AF9: 1 | AG9: S0001 | AH9: Indian investment abroad -in equity capital (shares)
A10: 100 | B10: Gross Amount | C10: =ROUND((L7/(100-A11*1)%),2) -> 26833.33 | D10: =D16 -> 86.028212 | E10: =ROUND(C10*D10,0) -> 2308423 | F10: =C7 -> USD | G10: =F10&C10 -> USD 26833.33 | K10: = | M10: =ROUNDUP((L7/(100-C13)%),2) -> 30492.43 | O10: Rs. | P10: =ROUND(M10*D16,0) -> 2623209 | AF10: 2 | AG10: S0002 | AH10: Indian investment abroad -in debt securities
A11: =C14 -> 10 | B11: TDS | C11: =ROUND((C10*A11%),2) -> 2683.33 | D11: =D10 -> 86.028212 | E11: =ROUND(C11*D11,0) -> 230842 | F11: =F10 -> USD | G11: =F11&C11 -> USD 2683.33 | H11: Nil | I11: NA | K11: / | O11: Rs. | P11: =ROUND(P10*C13%,0) -> 545627 | Q11: =O11&ROUND((E10*10.4%),0) -> Rs. 240076 | AF11: 3 | AG11: S0003 | AH11: Indian investment abroad -in branches and wholly owned subsidiaries
A12: =A10-A11 -> 90 | B12: Net Amount | C12: =C10-C11 -> 24150 | D12: =D11 -> 86.028212 | E12: =E10-E11 -> 2077581 | F12: =F11 -> USD | G12: =F12&C12 -> USD 24150 | K12: * | O12: Rs. | P12: =P10-P11 -> 2077582 | AF12: 4 | AG12: S0004 | AH12: Indian investment abroad -in subsidiaries and associates
B13: Tax Rate | C13: 20.8 | D13: % | G13: =C13&D13 -> 20.8% | AF13: 5 | AG13: S0005 | AH13: Indian investment abroad -in real estate
B14: DTAA Rate | C14: 10 | D14: % (Since TRC provided tax @ 10%) | G14: =C14&D14 -> 10% (Since TRC provided tax @ 10%) | O14: % | P14: =C14&O14 -> 10% | AF14: 6 | AG14: S0011 | AH14: Loans extended to Non-Residents
D15: (Since TRC not provided tax @ 25.75%) | G15: =C14&D15 -> 10 (Since TRC not provided tax @ 25.75%) | AF15: 7 | AG15: S0202 | AH15: Payment for operating expenses of Indian shipping companies operating abroad.
B16: Rate | C16: (approx) @ | D16: 86.028212 | E16: =C16&D16 -> (approx) @ 86.028212 | I16: 478719.32 | K16: 3290 | N16: =527753.67/6935 -> 76.100025 | AF16: 8 | AG16: S0208 | AH16: Operating expenses of Indian Airlines companies operating abroad
I17: =I16/6450 -> 74.22005 | AF17: 9 | AG17: S0212 | AH17: Booking of passages abroad – Airlines companies
B18: Gross Up | C18: Yes | D18: =D19&C12&K12&A10&K11&A12&K10&C10&E19 -> (24150*100/90=26833.33) | AF18: 10 | AG18: S0301 | AH18: Remittance towards business travel.
C19: No | D19: ( | E19: ) | AF19: 11 | AG19: S0302 | AH19: Travel under basic travel quota (BTQ)
AF20: 12 | AG20: S0303 | AH20: Travel for pilgrimage
AF21: 13 | AG21: S0304 | AH21: Travel for medical treatment
B22: BSR Code of the bank branch (7 digit) | C22: 6360106 | D22: "0410002" | E22: Axis/Yes | F22: =F23 -> 6160073 | AF22: 14 | AG22: S0305 | AH22: Travel for education (including fees, hostel expenses etc.)
D23: 6470101 | E23: SCB | F23: 6160073 | G23: Kotak Mahindra Bank Plot No. 586, Mahalaxmi Society, Vapi Daman Road, Chala, Vapi | AF23: 15 | AG23: S0401 | AH23: Postal services
G24: 5560065 | AF24: 16 | AG24: S0501 | AH24: Construction of projects abroad by Indian companies including import of goods at project site
AF25: 17 | AG25: S0602 | AH25: Freight insurance – relating to import and export of goods
B26: Proposed Date | C26: =C27+9+2+3+5 -> 45766 | AF26: 18 | AG26: S1011 | AH26: Payments for maintenance of offices abroad
B27: Date of deduction of tax at source | C27: =C28 -> 45747 | D27: Not Applicable | AF27: 19 | AG27: S1201 | AH27: Maintenance of Indian embassies abroad
B28: Date: | C28: 45747 | D28: 45177 | AF28: 20 | AG28: S1202 | AH28: Remittances by foreign embassies in India
B29: CA | C29: HG | AF29: 21 | AG29: S1301 | AH29: Remittance by non-residents towards family maintenance and savings
B30: **Certificate No. : | D30: =B30&C30 -> **Certificate No. : | AF30: 22 | AG30: S1302 | AH30: Remittance towards personal gifts and donations
AF31: 23 | AG31: S1303 | AH31: Remittance towards donations to religious and charitable institutions abroad
AF32: 24 | AG32: S1304 | AH32: Remittance towards grants and donations to other governments and charitable institutions established by the governments.
AF33: 25 | AG33: S1305 | AH33: Contributions or donations by the Government to international institutions
AF34: 26 | AG34: S1306 | AH34: Remittance towards payment or refund of taxes.
AF35: 27 | AG35: S1501 | AH35: Refunds or rebates or reduction in invoice value on account of exports
AF36: 28 | AG36: S1503 | AH36: Payments by residents for international bidding”.

Sheet 2015-16
A2: Sr. No. | B2: Company | C2: Vendor Description | D2: Vendor Code | E2: CA | F2: Country Name | G2: Certificate No. | H2: Document No. | I2: Invoice No. | J2: Document Date | K2: Currency | L2: Gross Amount | M2: TDS Amt. | N2: Net Amount | O2: INR Value | P2: TDS Beared | Q2: Nature | R2: TDS Rate | S2: GL Description | T2: VAT | U2: Address | V2: Article of IT | W2: Email ID | X2: Contact No. | Y2: Tax ID No.
C3: ='Revised Form15CB'!D20 -> K & C Medical Co. Ltd. | F3: ='Basic Data'!C6 -> Taiwan | H3: ='Basic Data'!N3 -> 19/35555 | I3: ='Basic Data'!O3 -> ML103/Mar/2025 | J3: ='Basic Data'!C28 -> 45747 | K3: ='Basic Data'!C7 -> USD | L3: ='Basic Data'!C10 -> 26833.33 | M3: ='Basic Data'!C11 -> 2683.33 | N3: ='Basic Data'!C12 -> 24150 | O3: ='Revised Form15CB'!F66 -> 2077581 | P3: Yes | Q3: ='Revised Form15CB'!E30 -> Consultancy fees | R3: ='Basic Data'!A11 -> 10 | U3: ='Revised Form15CB'!D21 -> 4F, No 53, Lane 147, Anxiang Road, Xindia District, New Taipei City, R.O.C. 10041 | V3: ='Revised Form15CB'!E42 -> Article 12 - Royalties and Fees for Technical Services of India-Taipei DTAA
